2020-03-13 02:19:50,543 ERROR: Exception on /index [GET] [in /home/ravil/Рабочий стол/microblog/venv/lib/python3.6/site-packages/flask/app.py:1891]
Traceback (most recent call last):
  File "/home/ravil/Рабочий стол/microblog/venv/lib/python3.6/site-packages/flask/app.py", line 2446, in wsgi_app
    response = self.full_dispatch_request()
  File "/home/ravil/Рабочий стол/microblog/venv/lib/python3.6/site-packages/flask/app.py", line 1951, in full_dispatch_request
    rv = self.handle_user_exception(e)
  File "/home/ravil/Рабочий стол/microblog/venv/lib/python3.6/site-packages/flask/app.py", line 1820, in handle_user_exception
    reraise(exc_type, exc_value, tb)
  File "/home/ravil/Рабочий стол/microblog/venv/lib/python3.6/site-packages/flask/_compat.py", line 39, in reraise
    raise value
  File "/home/ravil/Рабочий стол/microblog/venv/lib/python3.6/site-packages/flask/app.py", line 1947, in full_dispatch_request
    rv = self.preprocess_request()
  File "/home/ravil/Рабочий стол/microblog/venv/lib/python3.6/site-packages/flask/app.py", line 2241, in preprocess_request
    rv = func()
  File "/home/ravil/Рабочий стол/microblog/app/main/routes.py", line 17, in before_request
    g.locale = str(get_locale())
  File "/home/ravil/Рабочий стол/microblog/venv/lib/python3.6/site-packages/flask_babel/__init__.py", line 247, in get_locale
    babel = current_app.extensions['babel']
KeyError: 'babel'
2020-03-13 02:19:50,734 ERROR: Exception on /index [GET] [in /home/ravil/Рабочий стол/microblog/venv/lib/python3.6/site-packages/flask/app.py:1891]
Traceback (most recent call last):
  File "/home/ravil/Рабочий стол/microblog/venv/lib/python3.6/site-packages/flask/app.py", line 2446, in wsgi_app
    response = self.full_dispatch_request()
  File "/home/ravil/Рабочий стол/microblog/venv/lib/python3.6/site-packages/flask/app.py", line 1951, in full_dispatch_request
    rv = self.handle_user_exception(e)
  File "/home/ravil/Рабочий стол/microblog/venv/lib/python3.6/site-packages/flask/app.py", line 1820, in handle_user_exception
    reraise(exc_type, exc_value, tb)
  File "/home/ravil/Рабочий стол/microblog/venv/lib/python3.6/site-packages/flask/_compat.py", line 39, in reraise
    raise value
  File "/home/ravil/Рабочий стол/microblog/venv/lib/python3.6/site-packages/flask/app.py", line 1947, in full_dispatch_request
    rv = self.preprocess_request()
  File "/home/ravil/Рабочий стол/microblog/venv/lib/python3.6/site-packages/flask/app.py", line 2241, in preprocess_request
    rv = func()
  File "/home/ravil/Рабочий стол/microblog/app/main/routes.py", line 17, in before_request
    g.locale = str(get_locale())
  File "/home/ravil/Рабочий стол/microblog/venv/lib/python3.6/site-packages/flask_babel/__init__.py", line 247, in get_locale
    babel = current_app.extensions['babel']
KeyError: 'babel'
2020-03-13 02:19:51,091 ERROR: Exception on /index [GET] [in /home/ravil/Рабочий стол/microblog/venv/lib/python3.6/site-packages/flask/app.py:1891]
Traceback (most recent call last):
  File "/home/ravil/Рабочий стол/microblog/venv/lib/python3.6/site-packages/flask/app.py", line 2446, in wsgi_app
    response = self.full_dispatch_request()
  File "/home/ravil/Рабочий стол/microblog/venv/lib/python3.6/site-packages/flask/app.py", line 1951, in full_dispatch_request
    rv = self.handle_user_exception(e)
  File "/home/ravil/Рабочий стол/microblog/venv/lib/python3.6/site-packages/flask/app.py", line 1820, in handle_user_exception
    reraise(exc_type, exc_value, tb)
  File "/home/ravil/Рабочий стол/microblog/venv/lib/python3.6/site-packages/flask/_compat.py", line 39, in reraise
    raise value
  File "/home/ravil/Рабочий стол/microblog/venv/lib/python3.6/site-packages/flask/app.py", line 1947, in full_dispatch_request
    rv = self.preprocess_request()
  File "/home/ravil/Рабочий стол/microblog/venv/lib/python3.6/site-packages/flask/app.py", line 2241, in preprocess_request
    rv = func()
  File "/home/ravil/Рабочий стол/microblog/app/main/routes.py", line 17, in before_request
    g.locale = str(get_locale())
  File "/home/ravil/Рабочий стол/microblog/venv/lib/python3.6/site-packages/flask_babel/__init__.py", line 247, in get_locale
    babel = current_app.extensions['babel']
KeyError: 'babel'
2020-03-13 02:19:51,290 ERROR: Exception on /index [GET] [in /home/ravil/Рабочий стол/microblog/venv/lib/python3.6/site-packages/flask/app.py:1891]
Traceback (most recent call last):
  File "/home/ravil/Рабочий стол/microblog/venv/lib/python3.6/site-packages/flask/app.py", line 2446, in wsgi_app
    response = self.full_dispatch_request()
  File "/home/ravil/Рабочий стол/microblog/venv/lib/python3.6/site-packages/flask/app.py", line 1951, in full_dispatch_request
    rv = self.handle_user_exception(e)
  File "/home/ravil/Рабочий стол/microblog/venv/lib/python3.6/site-packages/flask/app.py", line 1820, in handle_user_exception
    reraise(exc_type, exc_value, tb)
  File "/home/ravil/Рабочий стол/microblog/venv/lib/python3.6/site-packages/flask/_compat.py", line 39, in reraise
    raise value
  File "/home/ravil/Рабочий стол/microblog/venv/lib/python3.6/site-packages/flask/app.py", line 1947, in full_dispatch_request
    rv = self.preprocess_request()
  File "/home/ravil/Рабочий стол/microblog/venv/lib/python3.6/site-packages/flask/app.py", line 2241, in preprocess_request
    rv = func()
  File "/home/ravil/Рабочий стол/microblog/app/main/routes.py", line 17, in before_request
    g.locale = str(get_locale())
  File "/home/ravil/Рабочий стол/microblog/venv/lib/python3.6/site-packages/flask_babel/__init__.py", line 247, in get_locale
    babel = current_app.extensions['babel']
KeyError: 'babel'
2020-03-13 02:20:35,477 INFO: Microblog startup [in /home/ravil/Рабочий стол/microblog/app/__init__.py:74]
